Workbook
Name AA: #REF!
Name ac: #REF!
Name acc: #REF!
Name ALAA: #REF!
Name bw: #REF!
Name car: #REF!
Name concrete: #REF!
Name COVER: #REF!
Name D: #REF!
Name DDD: #REF!
Name elec: #REF!
Name excavation: #REF!
Name fgfbnbfgh: #REF!
Name finish: #REF!
Name KING: #REF!
Name masonary: #REF!
Name metal: #REF!
Name plm: #REF!
Name PR: #REF!
Name RE: #REF!
Name roof: #REF!
Name sb: #REF!
Name soil: #REF!
Name YT: #REF!

Sheet Div.1.B
A1: Project: | C1: Commercial building
A2: Location: | C2: Al-DAMMAM , KSA
A3: Owner:
A4: Subject: | C4: Division 1A - EARTHWORKS
A5: DIV. # | C5: Description | D5: Unit | E5: Qty. | F5: Unit Price | G5: Total
A7: 1 | C7: EARTHWORKS
C8: Preambles
C9: Rates and prices in this BOQ shall be deemed to include all costs necessary for the execution of the Works which includes but not limited to the following
C10: 1. Cost of temporary and permanent works 2. All direct costs including labour, plant, materials, sub contractors, and the like 3. All indirect costs and preliminaries including Contractor's accomodations، offices, indirect labour, project sign board and equipment, superintendents and supervision staff, cost of bonds and insurances,waste containers. 4. Contractor's overheads and profit margins. 5. Coordination with other contractors and handing over the site to them. 6. Site security fencing and the like 7. All engineering works including design of shop drawings,material and other submittals in compliance with the specifications. 8. Compliance with all other requirements as per the Contract Documents.
A12: 1.1 | C12: Excavation
C13: Bulk Excavation in all type of soil (except rock) according to the substructure system limit indicated on the approved design drawings and in accordance to specifications and provided Geo-technical report, according to "Soil Report Ref. GT 1839-3339-24" Works also shall include the disposal of any surplus excavated materials off site subjected to the engineer instructions/contractor is responsible for submitting a compaction test report with minimum compaction of 95%.
A15: 1.1.1 | C15: Excavation (site leveling & waste removal ) | D15: M3 | E15: 1091 | F15: 36 | G15: =F15*E15 -> 39276
A18: 1.2 | C18: Backfilling -Around the tank and above footing up to bottom of basecoarse layer below sidewalk -Using natural clean sand (A-1 accoring to AASHTO) according to specifications -Compaction on layers, 30 cm for each. Until reach to 95% relative compation from maximum dry density for each layer. as per specifications by heavy roller - 15 ton min. -Item includes compaction test as per specefications.
C19: Backfill and soil replacement according to "Soil Report Ref. 3891". density all as per soil report and specifications.
A20: 1.2.1 | C20: Backfilling under footing (Soil Replacment) Backfilling for site (A-1 accoring to AASHTO) according to specifications according to site levels combantion test 95% every 30 cm with all neccecry works and as per soil test | D20: M3 | E20: 655 | F20: 74 | G20: =F20*E20 -> 48470
A21: 1.2.2 | C21: Backfilling Inbetween Footing & Grade Beam (sand) & SITE | D21: M3 | E21: 5635 | F21: 37 | G21: =F21*E21 -> 208495
A22: 1.2.3 | C22: Compacted subbase layer, 20 cm thick, under slab-on-grade for all shops, sales areas & service areas (A1B) – for site. | D22: M3 | E22: 285 | F22: 69 | G22: =F22*E22 -> 19665
A23: 1.2.4 | C23: Supply and application of approved anti-termite chemical treatment by spraying the soil beneath the Slab on Grade (SOG), including all necessary materials, equipment, labor, and related works, in accordance with the manufacturer’s recommendations. | D23: LS | E23: 1 | F23: 5503 | G23: =F23*E23 -> 5503
A25: TOTAL COST FOR DIVISION 1A: EARHTWORKS (To Summary) | G25: =SUM(G15:G24) -> 321409

Sheet Div.2.B
A1: Project: | C1: Commercial building
A2: Location: | C2: Al-DAMMAM , KSA
A3: Owner:
A4: Subject: | C4: Division 2A - CIVILWORKS
A5: DIV. # | C5: Description | D5: Unit | E5: Qty. | F5: Unit Price | G5: Total
A7: 2 | C7: CIVIL WORKS
C9: Concrete
C11: The contractor is referred to the specifications and drawings for all details related to the works and he is to include but not limited to for complying with all the requirements contained therein, whether or not they are specifically mentioned within the items. All Tender documents (Drawings, Bill of quantities, Specifications) are integrated documents and complete each other. Workshop drawings and frames for approval before supply and installation.contractor must submit concrete test report.
C13: Concrete
A15: 2.1 | C15: Plain Concrete Under Footing (2500 KG/CM2), Type (V) | D15: M3 | E15: 45 | F15: 379 | G15: =F15*E15 -> 17055
A17: 2.2 | C17: Footing Reinforced Concrete (4500 KG/CM2), Type (V) | D17: M3 | E17: 221 | F17: 890 | G17: =F17*E17 -> 196690
A19: 2.3 | C19: Pedestal (Height 1.00 m) (4500 KG/CM2), Type (V) | D19: M3 | E19: 29 | F19: 2165 | G19: =F19*E19 -> 62785
A21: 2.4 | C21: Plain Concrete Under Grade Beam (3000 KG/CM2), Type (V) | D21: M3 | E21: 28 | F21: 379 | G21: =F21*E21 -> 10612
A23: 2.5 | C23: Grade Beam (4500 KG/CM2), Type (V) | D23: M3 | E23: 118 | F23: 1315 | G23: =F23*E23 -> 155170
A25: 2.6 | C25: Slab On Grade (3000 KG/CM2), Type (I) | D25: M3 | E25: 197 | F25: 764 | G25: =F25*E25 -> 150508
A27: 2.7 | C27: Stiffener Column (Height 9.00 m) (4500 KG/CM2), Type (I) | D27: M3 | E27: 57 | F27: 1448 | G27: =F27*E27 -> 82536
A29: 2.8 | C29: Bond Beam & Slab (3000 KG/CM2), Type (I) | D29: M3 | E29: 173 | F29: 1315 | G29: =F29*E29 -> 227495
A31: 2.9 | C31: WATER TANKS Footing Reinforced Concrete (4500 KG/CM2), Type (V) | D31: M3 | E31: 33 | F31: 1065 | G31: =F31*E31 -> 35145
A33: 2.10 | C33: WATER TANKS Walls Reinforced Concrete (4500 KG/CM2), Type (V) | D33: M3 | E33: 16 | F33: 1128 | G33: =F33*E33 -> 18048
A35: 2.11 | C35: WATER TANKS Roof Reinforced Concrete (4500 KG/CM2), Type (V) | D35: M3 | E35: 27 | F35: 1128 | G35: =F35*E35 -> 30456
A38: 2.12 | C38: Protection Screed, 50mm thick, , Type (I) as per Drawings and Specification | D38: M2 | E38: 190 | F38: 32 | G38: =F38*E38 -> 6080
A40: 2.13 | C40: Plain concrete for site (2500 KG/CM2), Type (V) | D40: M3 | E40: 420 | F40: 379 | G40: =F40*E40 -> 159180
A42: TOTAL COST FOR DIVISION 2A: CIVILWORKS (To Summary) | G42: =SUM(G15:G40) -> 1151760

Sheet Div.3.B
A1: Project: | C1: Commercial building
A2: Location: | C2: Al-DAMMAM , KSA
A3: Owner:
A4: Subject: | C4: Division 3A -MASONRYWORKS
A5: DIV. # | C5: Description | D5: Unit | E5: Qty. | F5: Unit Price | G5: Total
A7: 3 | C7: MASONRY
C10: Concrete blocks bedded and jointed in cement sand mortar (1:3), including all necessary lintel beams, stiffener columns and reinforcement steel bars, solid block at jambs and all necessary ties, complete as shown on drawings.
A13: 3.1 | C13: 200 mm thick walls ConcreteBlock under boundary grade beams | D13: M2 | E13: 209 | F13: 86 | G13: =F13*E13 -> 17974
A17: 3.2 | C17: 200 mm thick walls ConcreteBlock for pumprooms-site rooms walls | D17: M2 | E17: 227 | F17: 86 | G17: =F17*E17 -> 19522
C18: total pcs=2838
A20: 3.3 | C20: 300 mm thick walls insulated ConcreteBlock for exterior walls | D20: M2 | E20: 2678 | F20: 187 | G20: =F20*E20 -> 500786
C21: building c&d =1120m2-14000 pcs building E=1558m2-19470 pcs
C22: total pcs=33,475
A27: TOTAL COST FOR DIVISION 3A: MASONRYWORKS (To Summary) | G27: =SUM(G13:G20) -> 538282

Sheet Div.4.B
A1: Project: | C1: Commercial building
A2: Location: | C2: Al-DAMMAM , KSA
A3: Owner:
A4: Subject: | C4: Division 4A - ARCHWORKS
A5: DIV. # | C5: Description | D5: Unit | E5: Qty. | F5: Unit Price | G5: Total
A7: 4 | C7: ARCHITECTURAL WORKS
C9: CONTRACTOR SHALL PROVIDE MATERIAL SAMPLES FOR ALL ITEM WITH SPECS FOR APPROVAL FROM OWNER & CONSULTANT
A11: 4.1 | C11: FLOORING WORKS
A13: 4.1.1 | C13: SUPPLY AND APPLY 2 MM THICK SELF-LEVELING EPOXY FLOORING SYSTEM (SIKA, FOSROC, OR APPROVED EQUIVALENT) FOR PUMP ROOMS, INCLUDING SURFACE PREPARATION BY MECHANICAL GRINDING, APPLICATION OF EPOXY PRIMER, SELF-LEVELING EPOXY COAT, AND FINAL SEALING COAT. COMPLETE IN ALL RESPECTS AS PER MANUFACTURER’S SPECIFICATIONS AND SITE REQUIREMENTS. | D13: Sq.M | E13: 16 | F13: 188 | G13: =F13*E13 -> 3008
A14: 4.1.2 | C14: SUPPLY & INSTALL GRAVEL BACKFILLING FOR SCECO ROOMS | D14: Sq.M | E14: 12 | F14: 32 | G14: =F14*E14 -> 384
A15: 4.1.3 | C15: SUPPLY AND INSTALL SAUDI GRANITE FLOORING 600 × 300 × 20 MM FOR SHOPS OUTDOOR (SITE), INCLUDING 5 CM THICK CEMENT-SAND MIX BED, FIXING USING ADHESIVE, JOINT GROUTING BETWEEN GRANITE TILES IN MATCHING COLOR, AND COMPLETE CLEANING AND POLISHING AFTER INSTALLATION. WORKS TO BE COMPLETE IN ALL RESPECTS. | D15: Sq.M | E15: 573 | F15: 165 | G15: =F15*E15 -> 94545
A16: 4.1.4 | C16: SUPPLY AND INSTALL SAUDI GRANITE FLOORING 600 × 600 × 20 MM FOR SITE WALKWAY, INCLUDING 5 CM THICK CEMENT-SAND MIX BED, FIXING USING ADHESIVE, JOINT GROUTING BETWEEN GRANITE TILES IN MATCHING COLOR, AND COMPLETE CLEANING AND POLISHING AFTER INSTALLATION. WORKS TO BE COMPLETE IN ALL RESPECTS. | D16: Sq.M | E16: 1582 | F16: 165 | G16: =F16*E16 -> 261030
A17: 4.1.5 | C17: SUPPLY & INSTALL CONRETE CURB STONE (300*150*500) FOR PAVEMENT SIDE WALKS | D17: L.M | E17: 280 | F17: 82 | G17: =F17*E17 -> 22960
A18: 4.1.6 | C18: SUPPLY & INTALL INTERLOCK FLOORING 20*10*6 CM FOR CAR PARKING & PAVING AREAS INCLUDING COMPACTED SUBBASE LAYER, 20 CM THICK, UNDER ALL INTERLOCK AREAS (A1B) - FOR SITE. THE WORKS INCLUDE ALL NECESSARY WORKS TO COMPLETE. | D18: Sq.M | E18: 448 | F18: 106 | G18: =F18*E18 -> 47488
A19: 4.1.7 | C19: SUPPLY & INTALL INTERLOCK FLOORING 20*10*8 CM FOR CAR PARKING & PAVING AREAS INCLUDING COMPACTED SUBBASE LAYER, 20 CM THICK, UNDER ALL INTERLOCK AREAS (A1B) - FOR SITE. THE WORKS INCLUDE ALL NECESSARY WORKS TO COMPLETE. | D19: Sq.M | E19: 31 | F19: 117 | G19: =F19*E19 -> 3627
A20: 4.1.8 | C20: SUPPLY AND INSTALLATION OF PRECAST CONCRETE PARKING WHEEL STOPS, SIZE 10 × 10 × 180 CM, INCLUDING ALL NECESSARY FIXINGS, ANCHORS, AND ACCESSORIES. WHEEL STOPS SHALL BE FINISHED WITH YELLOW ROAD-MARKING PAINT, SUCH AS JAZEERA ROAD PAINT OR APPROVED EQUIVALENT, SUITABLE FOR EXTERNAL PARKING APPLICATIONS, COMPLETE IN ACCORDANCE WITH THE PROJECT REQUIREMENTS. | D20: NO. | E20: 29 | F20: 225 | G20: =F20*E20 -> 6525
A21: 4.1.9 | C21: SUPPLY & INSTALL PORCLIEN FLOORING 600*600*11 FOR SERVICE ROOMS INDIAN ORIGIN | D21: Sq.M | E21: 31 | F21: 167 | G21: =F21*E21 -> 5177
A22: 4.1.10 | C22: SUPPLY & INSTALL PORCLIEN SKIRTING 600*100*11 FOR SERVICE ROOMS INDIAN ORIGIN | D22: L.M | E22: 40 | F22: 167 | G22: =F22*E22 -> 6680
A23: 4.2 | C23: FACADES WORK
A24: 4.2.1 | C24: EXTERNAL PLASTERING WORKS, INCLUDING SURFACE PREPARATION, CEMENT-SAND PLASTER APPLICATION, LEVELING WITH BOUGHS AND STRINGS, INSTALLATION OF GALVANISED ANGLE BEADS AT ALL CORNERS, REINFORCEMENT MESH AT COLUMNS, BEAMS, AND ABOVE ELECTRICAL, PLUMBING & HVAC PIPES, AND PROVIDING SMOOTH UNIFORM FINISH AS PER INDUSTRY STANDARDS. COMPLETE IN ALL RESPECTS. | D24: Sq.M | E24: 2605 | F24: 38 | G24: =F24*E24 -> 98990
A25: 4.2.2 | C25: SUPPLY AND INSTALLATION OF GRC FACADES SUPPLY AND INSTALLATION OF GRC (GLASS REINFORCED CONCRETE) FACADES IN ACCORDANCE WITH THE APPROVED DESIGN AND ARCHITECTURAL DRAWINGS, INCLUDING THE SUPPLY AND INSTALLATION OF 20 MM THICK GRC PANELS, COMPLETE WITH THE REQUIRED METAL FRAMING/SUBFRAME, BRACKETS, FIXINGS, ACCESSORIES, AND ALL NECESSARY OPENINGS, CUT-OUTS, AND RECESSES IN THE PANELS AS PER THE APPROVED DESIGN. THE SCOPE SHALL INCLUDE ALL MATERIALS, ACCESSORIES, FABRICATION, INSTALLATION, AND RELATED WORKS REQUIRED TO COMPLETE THE WORKS IN ACCORDANCE WITH THE APPROVED DRAWINGS, SPECIFICATIONS, AND RECOGNIZED TECHNICAL STANDARDS AND PRACTICES. | D25: Sq.M | E25: 414 | F25: 813 | G25: =F25*E25 -> 336582
A26: 4.2.3 | C26: PAINTING FOR OUTDOOR WALLS (RAL 9001) SUPPLY AND APPLY EXTERIOR WALL PAINT PROFILE PAINT FOR OUTDOOR SURFACES. THE PAINT SHALL BE MATT FINISH FROM ONE OF THE FOLLOWING APPROVED BRANDS: JOTUN, AL-JAZEERA, OR EQUIVALENT. SURFACE PREPARATION AND PAINTING SYSTEM: PRIMER / BASE COAT: 1 COAT. PUTTY / FILLER: 2 COATS. FINISH PAINT: 2 COATS OF MATT EXTERIOR PAINT. THE PAINT AND APPLICATION MUST COMPLY WITH THE SPECIFICATIONS OF THE EASTERN COAST ARCHITECTURE ACCORDING TO THE SAUDI BUILDING CODE. SURFACES MUST BE PROPERLY PREPARED, CLEANED, AND PRIMED AS REQUIRED BEFORE PAINTING. THE FINISH MUST BE UNIFORM, DURABLE, AND SUITABLE FOR EXTERIOR EXPOSURE UNDER LOCAL CLIMATE CONDITIONS. | D26: Sq.M | E26: 2896 | F26: 44 | G26: =F26*E26 -> 127424
A27: 4.2.4 | C27: PAINTING FOR OUTDOOR WALLS (RAL1011) SUPPLY AND APPLY EXTERIOR WALL PAINT PROFILE PAINT FOR OUTDOOR SURFACES. THE PAINT SHALL BE MATT FINISH FROM ONE OF THE FOLLOWING APPROVED BRANDS: JOTUN, AL-JAZEERA, OR EQUIVALENT. SURFACE PREPARATION AND PAINTING SYSTEM: PRIMER / BASE COAT: 1 COAT. PUTTY / FILLER: 2 COATS. FINISH PAINT: 2 COATS OF MATT EXTERIOR PAINT. THE PAINT AND APPLICATION MUST COMPLY WITH THE SPECIFICATIONS OF THE EASTERN COAST ARCHITECTURE ACCORDING TO THE SAUDI BUILDING CODE. SURFACES MUST BE PROPERLY PREPARED, CLEANED, AND PRIMED AS REQUIRED BEFORE PAINTING. THE FINISH MUST BE UNIFORM, DURABLE, AND SUITABLE FOR EXTERIOR EXPOSURE UNDER LOCAL CLIMATE CONDITIONS. | D27: Sq.M | E27: 207 | F27: 38 | G27: =F27*E27 -> 7866
A28: 4.2.5 | C28: PAINTING FOR OUTDOOR WALLS (RAL 0607005) BEHIND SIGNAGES SUPPLY AND APPLY EXTERIOR WALL PAINT PROFILE PAINT FOR OUTDOOR SURFACES. THE PAINT SHALL BE MATT FINISH FROM ONE OF THE FOLLOWING APPROVED BRANDS: JOTUN, AL-JAZEERA, OR EQUIVALENT. SURFACE PREPARATION AND PAINTING SYSTEM: PRIMER / BASE COAT: 1 COAT. PUTTY / FILLER: 2 COATS. FINISH PAINT: 2 COATS OF MATT EXTERIOR PAINT. THE PAINT AND APPLICATION MUST COMPLY WITH THE SPECIFICATIONS OF THE EASTERN COAST ARCHITECTURE ACCORDING TO THE SAUDI BUILDING CODE. SURFACES MUST BE PROPERLY PREPARED, CLEANED, AND PRIMED AS REQUIRED BEFORE PAINTING. THE FINISH MUST BE UNIFORM, DURABLE, AND SUITABLE FOR EXTERIOR EXPOSURE UNDER LOCAL CLIMATE CONDITIONS. | D28: Sq.M | E28: 263 | F28: 38 | G28: =F28*E28 -> 9994
A29: 4.3 | C29: EXTERNAL CLADDING
A30: 4.3.1 | C30: EXTERNAL STONE CLADDING SUPPLY AND INSTALLATION OF BEIGE TRAVERTINE STONE 400*800*20 MM CLADDING TO EXTERNAL FACADES, INCLUDING SURFACE PREPARATION, APPLICATION OF BLACK BITUMINOUS COATING (ASPHALT) TO MASONRY BLOCK WALLS PRIOR TO INSTALLATION, MECHANICAL FIXING SYSTEM USING HOT-DIP GALVANIZED STEEL ANGLES, GALVANIZED STEEL FASTENERS, BOLTS, AND STEEL ANCHORS AS REQUIRED, COMPLETE WITH ALL NECESSARY ACCESSORIES, CUTTING, DRILLING, JOINTS, ALIGNMENT, LEVELING, AND FINISHING, ALL IN ACCORDANCE WITH THE APPROVED SHOP DRAWINGS, MANUFACTURER'S RECOMMENDATIONS, AND THE OWNER'S APPROVED SAMPLE. | D30: Sq.M | E30: 44 | F30: 290 | G30: =F30*E30 -> 12760
A31: 4.3.2 | C31: RAZEEN SIGNAGE: SUPPLY, FABRICATION, AND INSTALLATION OF “RAZEEN SEEF MALL” EXTERNAL 3D SIGNAGE, INCLUDING INDIVIDUAL DIMENSIONAL LETTERS AND LOGO WITH BACKLIT LED ILLUMINATION, SUPPORTING STRUCTURE, FIXING ACCESSORIES, POWER SUPPLY, WIRING, AND ALL RELATED WORKS. SIGNAGE SHALL BE FABRICATED FROM HIGH-QUALITY, WEATHER-, UV-, AND CORROSION-RESISTANT MATERIALS, WITH ENERGY-EFFICIENT LED BACKLIGHTING PROVIDING UNIFORM WARM ILLUMINATION. THE CONTRACTOR SHALL SUBMIT SHOP DRAWINGS, MATERIAL SAMPLES, COLORS, FINISHES, STRUCTURAL DETAILS, AND ILLUMINATION DETAILS FOR APPROVAL PRIOR TO FABRICATION. COMPLETE WITH ALL BRACKETS, ANCHORS, CABLES, CONDUITS, LED DRIVERS, WEATHERPROOFING, AND ACCESSORIES. | D31: LS | E31: 1 | F31: 18750 | G31: =F31*E31 -> 18750
A33: TOTAL COST FOR DIVISION 4A: ARCHWORKS (To Summary) | G33: =SUM(G13:G32) -> 1063790

Sheet Div.5.B
A1: Project: | C1: Commercial building
A2: Location: | C2: Al-DAMMAM , KSA
A3: Owner:
A4: Subject: | C4: Division 5A - THERMALWORKS
A5: DIV. # | C5: Description | D5: Unit | E5: Qty. | F5: Unit Price | G5: Total
A7: 5 | C7: THERMAL AND MOISTURE PROTECTION
C8: The Contractor is referred to the specifications and drawings for all details related to the works of this division and he is to include but not limited to for complying with all the requirements contained therein, whether or ont they are specifically mentioned within the item. Scope of work will be: shop drawings issuem systems supply, installation and testing. All Tender documents( Drawings, Bill of quantities, Specifications) are integrated documents and complete each other.
C10: Waterproofing liquid membranes for all concrete foundations, Mechanical/Chemical Bonded (Fosroc/Grace) Water proofing system, as per Drawings and Specification
A12: 5.1 | C12: For Raft, Lift Pit & Retainging Wall | D12: LS | E12: 1
C14: External faces of Raft, Lift Pit & Retaining walls
F15: 22425 | G15: =F15*E12 -> 22425
C16: For Raft & Lift Pit
C18: Polythene sheet, 400 gauge, under blinding
C20: Horizontally laid under blinding
A22: 5.2 | C22: Supply and apply bituminous waterproofing materials for roofs and foundations of electrical rooms and pump-site rooms. Materials must be submitted for approval before execution. Work includes: -Apply 1 coat of primer. -Apply 2 coats of bituminous layer. -Install 2 layers of 4mm membrane with 10 cm overlaps. -Include skirting 30 cm all around. | D22: LS | E22: 1 | F22: 16689 | G22: =F22*E22 -> 16689
A24: 5.3 | C24: Waterproofing of Water Tanks (internal and external) Scope of Work: Waterproofing of water tanks to prevent leakage and protect the concrete. Includes the following steps: External Waterproofing: Build a solid masonry wall (20×20×40 cm blocks) around the tank (from the outside). Apply 2 coats of bitumen (primer not needed since 2 coats are specified). Install 2 layers of 4mm bituminous membrane with 10 cm overlaps (Membrane). Apply a protective layer over the membrane to safeguard it during backfilling and other construction works. Internal Waterproofing (after concrete works): Prepare and clean the concrete surface thoroughly from dust and debris. Apply tank-grade epoxy internal waterproofing with 1 mm thickness. Ensure full coverage of all surfaces and corners. Notes: All materials must be submitted for approval before execution. Includes all ancillary works such as surface preparation, membrane protection, and quality assurance of application. | D24: LS | E24: 1 | F24: 52243 | G24: =F24*E24 -> 52243
A26: 5.4 | C26: INSULATION FOR SANDWICH PANELROOF FLOORS 10CM (FOAM) | D26: M2 | E26: 1310 | F26: 88 | G26: =F26*E26 -> 115280
C27: contractor responsible for making all neccessery water tests to prevent any possible leakage
A30: TOTAL COST FOR DIVISION 5A: THERMALWORKS (To Summary) | G30: =SUM(G15:G29) -> 206637

Sheet Div.6.B
A1: Project: | C1: Commercial building
A2: Location: | C2: Al-DAMMAM , KSA
A3: Owner:
A4: Subject: | C4: Division 6A - GLASSWORKS
A5: DIV. # | C5: Description | D5: Unit | E5: Qty. | F5: Unit Price | G5: Total
A7: 6 | C7: DOORS & WINDOWS
C8: ALL DOORS AND ALUMINIUM (RALL1001) ARE FRAMLESS WITH U CHANEL FRAMES CONTRACTOR SUBMIT SAMBLES AND SHOPDRAWING OF GLASS AND ACCESSORIES
C10: DOORS
A11: 6.1 | B11: BUILDING C-D-E | C11: (D/W1) 15700*3000 ALUMINIUM GLASS WALL WITH THREE DOUBLE DOORS WITH FIXED GLASS @ SHOPS ENTRANCE | D11: NO. | E11: 2 | F11: 38269 | G11: =F11*E11 -> 76538
A13: 6.2 | B13: BUILDING C-D-E | C13: (D/W2) 13150*3000 ALUMINIUM GLASS WALL WITH TWO DOUBLE DOORS WITH FIXED GLASS @ SHOPS ENTRANCE | D13: NO. | E13: 1 | F13: 32054 | G13: =F13*E13 -> 32054
A15: 6.3 | B15: BUILDING C-D-E | C15: (D/W3) 12600*3000 ALUMINIUM GLASS WALL WITH TWO DOUBLE DOORS WITH FIXED GLASS @ SHOPS ENTRANCE | D15: NO. | E15: 2 | F15: 30713 | G15: =F15*E15 -> 61426
A17: 6.4 | B17: BUILDING C-D-E | C17: (D/W4) 12150*3000 ALUMINIUM GLASS WALL WITH TWO DOUBLE DOORS WITH FIXED GLASS @ SHOPS ENTRANCE | D17: NO. | E17: 1 | F17: 29616 | G17: =F17*E17 -> 29616
A19: 6.5 | B19: BUILDING C-D-E | C19: (D/W5) 3000*6500 ALUMINIUM GLASS WALL WITH DOUBLE DOORS WITH FIXED GLASS @ SHOPS ENTRANCE | D19: NO. | E19: 21 | F19: 15844 | G19: =F19*E19 -> 332724
A21: 6.6 | B21: BUILDING C-D-E | C21: (W01) FIXED ALUMINIUM GLASS WINDOW 2000*2500 @ SHOPS | D21: NO. | E21: 14 | F21: 3750 | G21: =F21*E21 -> 52500
A23: 6.7 | B23: BUILDING C-D-E | C23: (D01) 1100*2400 SINGLE LEAF WOODEN SWING SINGLE DOOR @ SERVICE ROOMS | D23: NO. | E23: 37 | F23: 3000 | G23: =F23*E23 -> 111000
A25: 6.8 | B25: BUILDING B | C25: (D2) 1100*2400 SINGLE LEAF STEEL SWING DOOR @ OFFICE, DATA & CONTROL, METER ROOM & PUMP ROOM. | D25: NO. | E25: 4 | F25: 3000 | G25: =F25*E25 -> 12000
A27: 6.9 | B27: BUILDING B | C27: (D3) 4500*2100 FOLDING SECO ROOM DOOR AS PER SECO STANDARD | D27: NO. | E27: 1 | F27: 5250 | G27: =F27*E27 -> 5250
A29: TOTAL COST FOR DIVISION 6A: GLASSWORKS (To Summary) | G29: =SUM(G11:G28) -> 713108

Sheet Div.7.B
A1: Project: | C1: Commercial building
A2: Location: | C2: Al-DAMMAM , KSA
A3: Owner:
A4: Subject: | C4: Division A7 - Plumbing
A6: DIV. # | C6: Description | D6: Unit | E6: Qty. | F6: Unit Price | G6: Total
A7: 7A
C8: Supply, install and test of complete plumbing accessories, pipes & fittings, excavation, backfilling, isolation, valves and other related works to have satisfactory operation of the whole system.
C10: Note:All plumbing materials and equipments tobe submitted for approval prior to installation.
B14: A | C14: SANITARY FIXTURES (AMERICAN STANDARD OR APPROVED EQUAL) & FITTINGS, COMPLETEWITH MIXER, FLUSH SYSTEM, ISOLATION VALVES AND ALL REQUIRED ACCESSORIES.
C15: Mirror Shelf
C16: Soap Holder
C17: Towel Rail
C18: Toilet Paper Holder
C19: Robe Hook
C20: Hand Dryer
B22: A.1 | C22: Western water closet (WWC), complete with accessories, flush tank type ,american style. | D22: NO | E22: 0
B23: A.2 | C23: Lavatory vanity, Counter top, complete with accessories. | D23: NO | E23: 0
B24: A.3 | C24: Lavatory vanity, pedestal (LAV), complete with accessories. | D24: NO | E24: 0
B26: A.4 | C26: Shower Tray with Mixer Faucet and Shower Head | D26: NO | E26: 0
B28: A.5 | C28: Mixer for (LAV) | D28: NO | E28: 0
B32: B | C32: POTABLE AND HOT WATER EQUIPMENT AND ACCESSORIES.
B33: B.1 | C33: Supply, install, connect and test central electric water heater (EWH) with 50 liters capacity | D33: NO | E33: 0
B34: B.2 | C34: Water Hammer Arrester (1/2" Dia.) - Wattsor approved equal | D34: NO | E34: 0
B35: B.3 | C35: Perennial Spray with Vacuum Breaker (1/2" Dia.) - Grohe or approved equal. | D35: NO | E35: 0
B42: C | C42: DOMESTIC WATER PIPING
C43: Supply and installation of pipe and fittings; CPVC Sch. 80; ASTM D1785; DOMESTIC WATER PIPING including elbows GATE valves, waterhammer arrestor and connections…Amarflex Rubber insulation ON HOT WATER LINES etc . (SAPPCO) or approved equal
B44: C.1 | C44: 76mm Ø CPVC pipe schedule 80 | D44: LM | E44: 14 | F44: 85 | G44: =F44*E44 -> 1190
B45: C.2 | C45: 63mm Ø CPVC pipe schedule 80 | D45: LM | E45: 20 | F45: 65 | G45: =F45*E45 -> 1300
B46: C.3 | C46: 50mm Ø CPVC pipe schedule 80 | D46: LM | E46: 232 | F46: 47 | G46: =F46*E46 -> 10904
B47: C.4 | C47: 25mm Ø CPVC pipe schedule 80 | D47: LM | E47: 485 | F47: 25 | G47: =F47*E47 -> 12125
B53: C.5 | C53: Domestic water fiber glass tank 3 m3 insulated fiberglass water tank with float switch interconnected to a booster pump at ROOF complete with valves, check valves, strainer as shown on the drawing. | D53: NO | E53: 8 | F53: 5625 | G53: =F53*E53 -> 45000
B56: D. | C56: WATER PUMPS
B58: D.1 | C58: Supply, install, connect, test and commission Transfer pump (TP-01) (TP-02) complete including pumps, valves, control panel, spare parts, accessories and all ancillary work as specified and as shown on drawings. set 1duty & 1stand by ( per pump set ) , VFD controlled at PUMP ROOM. (GRUNDFOS) or approved equal | D58: NO | E58: 1 | F58: 54500 | G58: =F58*E58 -> 54500
B64: D.2 | C64: Supply, install, connect, test and commission BOOSTER pump (PR-01),(PR-02),(PR-03),(PR-04),(PR-05),(PR-06) complete including pumps, valves, control panel, spare parts, accessories and all ancillary work as specified and as shown on drawings. set 1duty at upper roof. (GRUNDFOS) or approved equal | D64: NO | E64: 4 | F64: 6250 | G64: =F64*E64 -> 25000
B72: E | C72: SANITARY WASTE PIPING
C74: The contractor shall supply and install all the following items including all necessary accessories required for proper operations and all materials required for erection and installation. The price of all TIE-inconnections, elbows, reducers, Y-branches and all necessary fittings, excavation, backfilling, bedding shall be considered within the unit prices of pipes. (SAPPCO) or approved equal
B77: E.1 | C77: 160mm Ø PVC pipe, class 4 | D77: LM | E77: 164 | F77: 192 | G77: =F77*E77 -> 31488
B78: E.2 | C78: 110mm Ø PVC pipe, class 4 | D78: LM | E78: 83 | F78: 125 | G78: =F78*E78 -> 10375
B79: E.3 | C79: 75mm Ø PVC pipe, class 4 FOR HVAC SELVEE PIPES FROM SHOPS TO ROOF TOP | D79: LM | E79: 78 | F79: 67 | G79: =F79*E79 -> 5226
B81: E.4 | C81: GROUND Clean Out :
...

Sheet Div.8.B
A1: Project: | C1: Commercial building
A2: Location: | C2: Al-DAMMAM , KSA
A3: Owner:
A4: Subject: | C4: Division A8 - Electrical
A6: DIV. # | C6: Description | D6: Unit | E6: Qty. | F6: Unit Price | G6: Total
A7: 8
C8: DIVISION 16 - ELECTRICAL
C10: All the electrical works include related works which
C11: required to complete the work but not mentioned
C12: in here or not shown in drawings, such as
C13: demolition, excavation, backfilling, concreting,
C14: drilling, labels of cables and panel boards, pipes,
C15: boxes, fasting devices, test and commissioning. | D15: Note
C17: All electrical works shall be constructed according
C18: to the SASO and latest SEC code. | D18: Note
C22: SITE WORK :-
B24: A | C24: MAIN AND SUB MAIN POWER
B26: 1 | C26: Main and Sub-Main Circuit:
C27: 600/1000V XLPE multicore or single core copper
C28: cable in conduits including UPVC conduits,
C29: conductors, junction boxes, connection for
C30: feeders at various power loads
C31: as shown on drawings.
B33: 1.1 | C33: 2X(4C-300 mm2+1X70 mm2G) | D33: LM | E33: 0 | F33: 1384 | G33: =F33*E33 -> 0
B34: 1.2 | C34: 4C-95mm2+1X50mm2G | D34: LM | E34: 11 | F34: 251 | G34: =F34*E34 -> 2761
B35: 1.3 | C35: 4C-185mm2+1X50mm2G | D35: LM | E35: 45 | F35: 466 | G35: =F35*E35 -> 20970
B36: 1.4 | C36: 4C-50mm2+1X35mm2G | D36: LM | E36: 1188 | F36: 141 | G36: =F36*E36 -> 167508
B37: 1.5 | C37: 4C-35mm2+1X16mm2G | D37: LM | E37: 9 | F37: 104 | G37: =F37*E37 -> 936
B38: 1.6 | C38: 4C-25mm2+1X16mm2G | D38: LM | E38: 64 | F38: 84 | G38: =F38*E38 -> 5376
B39: 1.7 | C39: 4C-10mm2+1X10mm2G | D39: LM | E39: 12 | F39: 50 | G39: =F39*E39 -> 600
B43: 2 | C43: Supply and install main distribution panelboards including circuit breakers, fixings and all assocciated works as required and as shown on drawings.
B46: 2.1 | C46: MDB-1 | D46: NO | E46: 0 | F46: 0 | G46: =F46*E46 -> 0
B47: 2.2 | C47: MDB-2 | D47: NO | E47: 0 | F47: 0 | G47: =F47*E47 -> 0
B48: 2.3 | C48: MDB-3 | D48: NO | E48: 1 | F48: 9913 | G48: =F48*E48 -> 9913
B49: 2.4 | C49: PK | D49: NO | E49: 0 | F49: 0 | G49: =F49*E49 -> 0
A50: 35 | B50: 2.5 | C50: LP-EX & LP-EX -2 | D50: NO | E50: 1 | F50: 3417 | G50: =F50*E50 -> 3417
B51: 2.6 | C51: PC-1 | D51: NO | E51: 1 | F51: 3417 | G51: =F51*E51 -> 3417
B52: 2.7 | C52: PC-2 | D52: NO | E52: 1 | F52: 3417 | G52: =F52*E52 -> 3417
B53: 2.8 | C53: PS-01 | D53: NO | E53: 0 | F53: 0 | G53: =F53*E53 -> 0
B54: 2.9 | C54: PS-02 | D54: NO | E54: 0 | F54: 0 | G54: =F54*E54 -> 0
...

Sheet Div.9.B
A1: Project: | C1: Commercial building
A2: Location: | C2: Al-DAMMAM , KSA
A3: Owner:
A4: Subject: | C4: Division A9 - FIRE
A6: DIV. # | C6: Description | D6: Unit | E6: Qty. | F6: Unit Price | G6: Total
C8: DIVISION 17 - FIRE SYSTEM
C10: Fire Alarm items
B11: Fa | C11: FIRE ALARM SYSTEM : Alarm systems include the supply, installation, testing and commissioning of the fire alarm system, and the work includes wires, pipes, cable beds, boxes, supports, grounding ,all fittings ,accessories,exacavations,backfilling,and all labour and materials to complete work.The entire system materials and installation must be complied the NFPA and all materials and components comply with Saudi Standard Specifications (SASO) or UL / FM Listed and civil defense requirements. All materials must be approved before supply by the engineer owner .
B12: Fa1 | C12: Addressable fire alarm control panel ( 1 loop ) with 24 hour back up battery. | D12: Pcs | E12: 1 | F12: 7000 | G12: =F12*E12 -> 7000
B13: Fa2 | C13: Addressable manual call point | D13: Pcs | E13: 1 | F13: 813 | G13: =F13*E13 -> 813
B14: Fa3 | C14: Addressable siren ( indoor ) | D14: Pcs | E14: 1 | F14: 813 | G14: =F14*E14 -> 813
B15: Fa4 | C15: Addressable Smoke Detector | D15: Pcs | E15: 2 | F15: 482 | G15: =F15*E15 -> 964
B16: Fa5 | C16: Addressable Heat Detector | D16: Pcs | E16: 1 | F16: 482 | G16: =F16*E16 -> 482
B17: Fa6 | C17: Addressable weatherproof alarm siren with flashing light | D17: Pcs | E17: 6 | F17: 813 | G17: =F17*E17 -> 4878
B18: Fa7 | C18: Monitor module | D18: Pcs | E18: 30 | F18: 1000 | G18: =F18*E18 -> 30000
B19: Fa8 | C19: Conventional fire alarm control panel ( 2 Zoons ) with 24 hour back up battery. | D19: Pcs | E19: 0 | F19: 2250 | G19: =F19*E19 -> 0
B20: Fa9 | C20: Conventional fire alarm control panel ( 1 Zoon ) with 24 hour back up battery. | D20: Pcs | E20: 24 | F20: 2063 | G20: =F20*E20 -> 49512
B21: Fa10 | C21: Conventional manual call point | D21: Pcs | E21: 24 | F21: 563 | G21: =F21*E21 -> 13512
B22: Fa11 | C22: Conventional Bell | D22: Pcs | E22: 24 | F22: 563 | G22: =F22*E22 -> 13512
B23: Fa12 | C23: Conventional Smoke Detector | D23: Pcs | E23: 48 | F23: 282 | G23: =F23*E23 -> 13536
... B27: Fa16 | C27: FIRE RATED METAL DOOR SELF CLOSE 1.0 HOUR | D27: NO | E27: 0 | F27: 3438 | G27: =F27*E27 -> 0
C31: FIRE PROTECTION SYSTEM
B33: FB | C33: Supply, installation and testing of pipework, seamless
C34: black steel pipe, schedule 40 ASTM A 53 or A795; fittings
C35: shall be malleable iron screwed for 50mm OD and below;
C36: steel flanges & flanged fittings shall be ANSI B16.5 dim.,
C37: class 150-ASTM A105; for aboveground pipe shall be
C38: RTR as per ASTM D2310, bell x spigot and for adhesive
C39: bonded joints: including supports as shown on drawing
C40: standard and specifications:
B42: FB1 | C42: 1" Ø pipe schedule 40 | D42: LM | E42: 326 | F42: 48 | G42: =F42*E42 -> 15648
B44: FB2 | C44: 1.25" Ø pipe schedule 40 | D44: LM | E44: 0 | F44: 61 | G44: =F44*E44 -> 0
B46: FB3 | C46: 1.5" Ø pipe schedule 40 | D46: LM | E46: 74 | F46: 73 | G46: =F46*E46 -> 5402
B48: FB4 | C48: 2" Ø pipe schedule 40 | D48: LM | E48: 43 | F48: 108 | G48: =F48*E48 -> 4644
B50: FB5 | C50: 2.5" Ø pipe schedule 40 | D50: LM | E50: 40 | F50: 144 | G50: =F50*E50 -> 5760
B52: FB6 | C52: 3.0" Ø pipe schedule 40 | D52: LM | E52: 41 | F52: 186 | G52: =F52*E52 -> 7626
B54: FB7 | C54: 4.0" Ø pipe schedule 40 | D54: LM | E54: 45 | F54: 253 | G54: =F54*E54 -> 11385
C56: CONTRACTOR IS RESPONSBLE FOR (excavation, levelling, installation, concrete thrust blocks, tests, backfilling and warning tape
B58: FB8 | C58: HDPE PIPE UNDER GROUND 2 INCH | D58: LM | E58: 94 | F58: 47 | G58: =F58*E58 -> 4418
B60: FB9 | C60: HDPE PIPE UNDER GROUND 3 INCH | D60: LM | E60: 20 | F60: 68 | G60: =F60*E60 -> 1360
...

Sheet Div.10.B
A1: Project: | C1: Commercial building
A2: Location: | C2: Al-DAMMAM , KSA
A3: Owner:
A4: Subject: | C4: Division A10 - METALWORKS
A5: DIV. # | C5: Description | D5: Unit | E5: Qty. | F5: Unit Price | G5: Total
A7: 10 | C7: METALS
A11: 10.1 | C11: Install, and Erection of Pre Engineered Structural steel works including rafters, purlins,platform above roof for water tanks & hvac outdoor unit | D11: LS | E11: 1 | F11: 94875 | G11: =F11*E11 -> 94875
C12: fixing 100mm thk Sandwich panels to Roof (0.50mm thk GI (G90) Polysterstandard RAL colour Top skin,50mm thk PIT of density35/40 +/-3kg/m³,0.70 thk thk GI (G90) Polysterstandard RAL colour Liner skin
A14: 10.2 | C14: METAL STAIR LADDER FOR ROOF SERVICE HIGHT 11 METER | D14: NO | E14: 3 | F14: 20625 | G14: =F14*E14 -> 61875
A16: 10.3 | C16: METAL CNC DESIGN FOR FAÇADE AS PER DESIGN RAL (9001) | D16: LS | E16: 1 | F16: 18750 | G16: =F16*E16 -> 18750
C19: The Supplier Nominated by client to undertake the above works ALMGHRABY Can be contacted via below contact details.(Tenderers are requested to contact ALMGHRABY Via below contact details)
A21: TOTAL COST FOR DIVISION 10: FIRE (To Summary) | G21: =SUM(G11:G20) -> 175500

Sheet SUMMARY
A1: Project: | D1: Commercial building
A2: Location: | D2: Al-DAMMAM , KSA
A3: Owner:
A5: COMPOSITE SUMMARY
A6: Item No. | C6: Description | D6: Unit | E6: Qty. | F6: Unit Rate | G6: Amount
G7: SAR
A9: 1 | C9: EARTHWORKS | D9: XXX | E9: XXX | F9: XXX | G9: ='Div.1.B'!$G$25 -> 321409
A11: 2 | C11: CIVIL WORKS | D11: XXX | E11: XXX | F11: XXX | G11: ='Div.2.B'!$G$42 -> 1151760
A13: 3 | C13: MASONRY | D13: XXX | E13: XXX | F13: XXX | G13: ='Div.3.B'!$G$27 -> 538282
A15: 4 | C15: ARCHITECTURAL WORKS | D15: XXX | E15: XXX | F15: XXX | G15: ='Div.4.B'!$G$33 -> 1063790
A17: 5 | C17: THERMAL & MOISTURE PROTECTION | D17: XXX | E17: XXX | F17: XXX | G17: ='Div.5.B'!$G$30 -> 206637
A19: 6 | C19: DOORS & WINDOWS | D19: XXX | E19: XXX | F19: XXX | G19: ='Div.6.B'!$G$29 -> 713108
A21: 7 | C21: PLUMBING | D21: XXX | E21: XXX | F21: XXX | G21: ='Div.7.B'!$G$135 -> 323601
A23: 8 | C23: ELECTRICAL | D23: XXX | E23: XXX | F23: XXX | G23: ='Div.8.B'!$G$239 -> 656812
A25: 9 | C25: FIRE PROTECTION SYSTEM | D25: XXX | E25: XXX | F25: XXX | G25: ='Div.9.B'!$G$143 -> 407656
A27: 10 | C27: Steel structure erection | D27: XXX | E27: XXX | F27: XXX | G27: ='Div.10.B'!$G$21 -> 175500
C29: TOTAL ESTIMATED CONTRACT PRICE | G29: =SUM(G9:G28) -> 5558555
